Workbook

Sheet Intro
A1: Ileal amino acid digestibility and DIAAS values of world foods
A3: Prepared by: Dr. Molly Muleya (Future Protein Platform, University of Nottingham, United Kingdom)

Sheet IAA digestibility
A1: Food item name | B1: Food group | C1: Data source | D1: Model | E1: Method | F1: Protein | G1: TRP | H1: THR | I1: ILE | J1: LEU | K1: LYS | L1: MET | M1: CYS | N1: PHE | O1: TYR | P1: VAL | Q1: ARG | R1: HIS | S1: Additional information
F2: Digestibility Coefficients
A3: Barley (not hulless varieties) | B3: Cereal & cereal products | C3: 2 | D3: Pig | E3: Standardized Ileal | F3: 0.8 | G3: 0.79 | H3: 0.75 | I3: 0.81 | J3: 0.83 | K3: 0.75 | L3: 0.83 | M3: 0.84 | N3: 0.84 | O3: 0.83 | P3: 0.8 | Q3: 0.83 | R3: 0.81
A4: Barley, dehulled (11,8% protein) | B4: Cereal & cereal products | C4: 7 | D4: Pig | E4: Standardized Ileal | F4: 0.745 | G4: 0.84 | H4: 0.72 | I4: 0.76 | J4: 0.79 | K4: 0.74 | L4: 0.78 | M4: 0.8 | N4: 0.82 | O4: 0.77 | P4: 0.77 | Q4: 0.82 | R4: 0.81 | S4: Pocured from Siemer Enterprises Inc.
A5: Biscuits (CP>12%) | B5: Cereal & cereal products | C5: 1 | D5: Human(Predicted) | E5: Standardized Ileal | F5: 0.91 | G5: 0.86 | H5: 0.91 | I5: 0.92 | J5: 0.91 | K5: 0.89 | L5: 0.9 | M5: 0.87 | N5: 0.88 | O5: 0.94 | P5: 0.9 | Q5: 0.93 | R5: 0.93
A6: Bread | B6: Cereal & cereal products | C6: 1 | D6: Human(Predicted) | E6: Standardized Ileal | F6: 0.91 | G6: 0.9 | H6: 0.91 | I6: 0.92 | J6: 0.93 | K6: 0.92 | L6: 0.93 | M6: 0.87 | N6: 0.88 | O6: 0.93 | P6: 0.91 | Q6: 0.93 | R6: 0.92
A7: Maize flour/Corn flour | B7: Cereal & cereal products | C7: 1 | D7: Human(Predicted) | E7: Standardized Ileal | F7: 0.82 | G7: 0.78 | H7: 0.76 | I7: 0.86 | J7: 0.92 | K7: 0.76 | L7: 0.92 | M7: 0.79 | N7: 0.84 | O7: 0.91 | P7: 0.85 | Q7: 0.84 | R7: 0.84
A8: Maize/corn | B8: Cereal & cereal products | C8: 2 | D8: Pig | E8: Standardized Ileal | F8: 0.86 | G8: 0.8 | H8: 0.83 | I8: 0.88 | J8: 0.93 | K8: 0.8 | L8: 0.91 | M8: 0.89 | N8: 0.91 | O8: 0.9 | P8: 0.87 | Q8: 0.91 | R8: 0.89
A9: Maize (extruded)/extruded corn | B9: Cereal & cereal products | C9: 2 | D9: Pig | E9: Standardized Ileal | F9: 0.86 | G9: 0.83 | H9: 0.81 | I9: 0.87 | J9: 0.91 | K9: 0.79 | L9: 0.89 | M9: 0.87 | N9: 0.9 | O9: 0.89 | P9: 0.86 | Q9: 0.89 | R9: 0.87
A10: Maize (flaked)/flaked corn/rolled corn | B10: Cereal & cereal products | C10: 2 | D10: Pig | E10: Standardized Ileal | F10: 0.86 | G10: 0.83 | H10: 0.81 | I10: 0.87 | J10: 0.91 | K10: 0.79 | L10: 0.89 | M10: 0.87 | N10: 0.9 | O10: 0.89 | P10: 0.86 | Q10: 0.89 | R10: 0.87
A11: Maize (high moisure)/humid corn - 60-70% dry matter, raw | B11: Cereal & cereal products | C11: 2 | D11: Pig | E11: Standardized Ileal | F11: 0.86 | G11: 0.8 | H11: 0.83 | I11: 0.88 | J11: 0.93 | K11: 0.8 | L11: 0.91 | M11: 0.88 | N11: 0.91 | O11: 0.9 | P11: 0.87 | Q11: 0.91 | R11: 0.89
A12: Maize bran | B12: Cereal & cereal products | C12: 1 | D12: Human(Predicted) | E12: Standardized Ileal | F12: 0.72 | G12: 0.69 | H12: 0.66 | I12: 0.77 | J12: 0.81 | K12: 0.68 | L12: 0.83 | M12: 0.69 | N12: 0.8 | O12: 0.8 | P12: 0.77 | Q12: 0.88 | R12: 0.8
A13: Maize, yellow dent (7,5% protein) | B13: Cereal & cereal products | C13: 7 | D13: Pig | E13: Standardized Ileal | F13: 0.702 | G13: 0.7 | H13: 0.7 | I13: 0.76 | J13: 0.84 | K13: 0.75 | L13: 0.9 | M13: 0.77 | N13: 0.83 | O13: 0.8 | P13: 0.75 | Q13: 0.81 | R13: 0.83 | S13: Procured from Exseed Genetics LLC
A14: Maize, nutridense (8,8% protein) | B14: Cereal & cereal products | C14: 7 | D14: Pig | E14: Standardized Ileal | F14: 0.764 | G14: 0.73 | H14: 0.76 | I14: 0.81 | J14: 0.9 | K14: 0.79 | L14: 0.91 | M14: 0.82 | N14: 0.88 | O14: 0.85 | P14: 0.82 | Q14: 0.87 | R14: 0.87 | S14: Procured from Exseed Genetics LLC
A15: Maize, high lysine | B15: Cereal & cereal products | C15: 16 | D15: Pig | E15: Standardized Ileal | F15: 0.91 | G15: 0.92 | H15: 0.92 | I15: 0.85 | J15: 1.05 | K15: 0.83 | L15: 0.92 | M15: 0.92 | N15: 0.95 | O15: 0.92 | P15: 0.95 | Q15: 0.96 | R15: 0.86 | S15: Values in red are calculated average AA digestibility
A16: Millet, finger | B16: Cereal & cereal products | C16: 4 | D16: Human | E16: True Ileal | F16: 0.723 | G16: 0.723 | H16: 0.672 | I16: 0.754 | J16: 0.672 | K16: 0.745 | L16: 0.601 | M16: 0.723 | N16: 0.964 | O16: 0.723 | P16: 0.653 | Q16: 0.723 | R16: 0.723 | S16: Values in red are calculated average AA digestibility
A17: Millet, pearl (Penisetum glaucum (l) R. Br)/candle millet/dark millet/bajra/Indian millet/horse millet/bulrush millet/cattail millet | B17: Cereal & cereal products | C17: 2 | D17: Pig | E17: Standardized Ileal | F17: 0.88 | G17: 0.92 | H17: 0.87 | I17: 0.91 | J17: 0.91 | K17: 0.86 | L17: 0.84 | M17: 0.9 | N17: 0.93 | O17: 0.87 | P17: 0.9 | Q17: 0.93 | R17: 0.92
A18: Millet, proso (Panicum miliaceum L.)/common millet/broomtail millet/hog millet/white millet/broomcorn millet | B18: Cereal & cereal products | C18: 2 | D18: Pig | E18: Standardized Ileal | F18: 0.844 | G18: 0.77 | H18: 0.76 | I18: 0.81 | J18: 0.83 | K18: 0.77 | L18: 0.84 | M18: 0.75 | N18: 0.84 | O18: 0.82 | P18: 0.79 | Q18: 0.88 | R18: 0.82
A19: Oat groats (Avena sativa L.)/oat grain from whuch hulls have been removed | B19: Cereal & cereal products | C19: 2 | D19: Pig | E19: Standardized Ileal | F19: 0.79 | G19: 0.82 | H19: 0.8 | I19: 0.83 | J19: 0.83 | K19: 0.79 | L19: 0.85 | M19: 0.85 | N19: 0.83 | O19: 0.85 | P19: 0.81 | Q19: 0.86 | R19: 0.83
A20: Oats (Avena sativa L.) | B20: Cereal & cereal products | C20: 1 | D20: Human(Predicted) | E20: Standardized Ileal | F20: 0.74 | G20: 0.77 | H20: 0.7 | I20: 0.8 | J20: 0.82 | K20: 0.76 | L20: 0.82 | M20: 0.72 | N20: 0.84 | O20: 0.81 | P20: 0.79 | Q20: 0.88 | R20: 0.85
A21: Oats (Avena sativa L.) | B21: Cereal & cereal products | C21: 2 | D21: Pig | E21: Standardized Ileal | F21: 0.76 | G21: 0.78 | H21: 0.69 | I21: 0.79 | J21: 0.81 | K21: 0.73 | L21: 0.84 | M21: 0.75 | N21: 0.84 | O21: 0.8 | P21: 0.77 | Q21: 0.88 | R21: 0.83
A22: Oats, flaked/flaked or rolled oat grain | B22: Cereal & cereal products | C22: 2 | D22: Pig | E22: Standardized Ileal | F22: 0.76 | G22: 0.78 | H22: 0.69 | I22: 0.79 | J22: 0.81 | K22: 0.73 | L22: 0.84 | M22: 0.75 | N22: 0.93 | O22: 0.79 | P22: 0.77 | Q22: 0.88 | R22: 0.83
A23: Oats, dehulled (13,1% protein) | B23: Cereal & cereal products | C23: 7 | D23: Pig | E23: Standardized Ileal | F23: 0.846 | G23: 0.82 | H23: 0.81 | I23: 0.87 | J23: 0.87 | K23: 0.86 | L23: 0.9 | M23: 0.77 | N23: 0.88 | O23: 0.81 | P23: 0.85 | Q23: 0.9 | R23: 0.88 | S23: Pocured from Siemer Enterprises Inc
A24: Rice | B24: Cereal & cereal products | C24: 1 | D24: Human(Predicted) | E24: Standardized Ileal | F24: 0.9 | G24: 0.89 | H24: 0.82 | I24: 0.75 | J24: 0.81 | K24: 0.92 | L24: 0.86 | M24: 0.97 | N24: 0.86 | O24: 0.79 | P24: 0.88 | Q24: 0.9 | R24: 0.99
A25: Rice, brown (Oryza sativa L.)/unpolished rice without the hulls but with the outer grain layers | B25: Cereal & cereal products | C25: 2 | D25: Pig | E25: Standardized Ileal | F25: 0.876 | G25: 0.85 | H25: 0.84 | I25: 0.86 | J25: 0.88 | K25: 0.86 | L25: 0.89 | M25: 0.85 | N25: 0.89 | O25: 0.88 | P25: 0.86 | Q25: 0.92 | R25: 0.88
A26: Rice, paddy/whole rice grain with the hulls included | B26: Cereal & cereal products | C26: 2 | D26: Pig | E26: Standardized Ileal | F26: 0.745 | G26: 0.76 | H26: 0.75 | I26: 0.8 | J26: 0.82 | K26: 0.75 | L26: 0.83 | M26: 0.73 | N26: 0.83 | O26: 0.81 | P26: 0.78 | Q26: 0.87 | R26: 0.8
A27: Rice, polished, broken (byproduct of the polishing process consisting of small or broken grains) | B27: Cereal & cereal products | C27: 2 | D27: Pig | E27: Standardized Ileal | F27: 0.911 | G27: 0.95 | H27: 0.94 | I27: 0.94 | J27: 0.95 | K27: 0.94 | L27: 0.94 | M27: 0.94 | N27: 0.94 | O27: 0.82 | P27: 0.95 | Q27: 0.97 | R27: 0.94
A28: Rice, white, polished (9,0% protein) | B28: Cereal & cereal products | C28: 7 | D28: Pig | E28: Standardized Ileal | F28: 0.881 | G28: 0.95 | H28: 0.91 | I28: 0.92 | J28: 0.94 | K28: 0.92 | L28: 0.95 | M28: 0.94 | N28: 0.95 | O28: 0.92 | P28: 0.94 | Q28: 0.92 | R28: 0.91 | S28: Procured from Walmart
A29: Rice bran | B29: Cereal & cereal products | C29: 1 | D29: Human(Predicted) | E29: Standardized Ileal | F29: 0.65 | G29: 0.72 | H29: 0.64 | I29: 0.67 | J29: 0.67 | K29: 0.69 | L29: 0.73 | M29: 0.65 | N29: 0.68 | O29: 0.79 | P29: 0.66 | Q29: 0.82 | R29: 0.77
A30: Rye (Secale cereale L.) | B30: Cereal & cereal products | C30: 2 | D30: Pig | E30: Standardized Ileal | F30: 0.77 | G30: 0.76 | H30: 0.71 | I30: 0.77 | J30: 0.78 | K30: 0.72 | L30: 0.81 | M30: 0.84 | N30: 0.82 | O30: 0.77 | P30: 0.75 | Q30: 0.8 | R30: 0.79
A31: Rye (12,1% protein) | B31: Cereal & cereal products | C31: 7 | D31: Pig | E31: Standardized Ileal | F31: 0.706 | G31: 0.75 | H31: 0.64 | I31: 0.72 | J31: 0.74 | K31: 0.67 | L31: 0.8 | M31: 0.76 | N31: 0.79 | O31: 0.66 | P31: 0.71 | Q31: 0.79 | R31: 0.77 | S31: Pocured from Siemer Enterprises Inc
A32: Seitan (wheat based protein), 20,9 g/100 g protein) | B32: Cereal & cereal products | C32: 8 | D32: Pig | E32: True Ileal | F32: 0.94 | G32: 0.922 | H32: 0.941 | I32: 0.961 | J32: 0.964 | K32: 0.978 | L32: 0.978 | M32: 0.99 | N32: 0.999 | O32: 0.944 | P32: 0.968 | Q32: 0.947 | R32: 0.956 | S32: Commercial origin
A33: Sorghum (Sorghum bicolor (L) Moench, low tannin variety | B33: Cereal & cereal products | C33: 2 | D33: Pig | E33: Standardized Ileal | F33: 0.79 | G33: 0.79 | H33: 0.76 | I33: 0.83 | J33: 0.86 | K33: 0.74 | L33: 0.85 | M33: 0.77 | N33: 0.85 | O33: 0.85 | P33: 0.81 | Q33: 0.82 | R33: 0.78
A34: Sorghum (Sorghum bicolor (L) Moench, low tannin variety | B34: Cereal & cereal products | C34: 1 | D34: Human(Predicted) | E34: Standardized Ileal | F34: 0.83 | G34: 0.87 | H34: 0.84 | I34: 0.87 | J34: 0.88 | K34: 0.79 | L34: 0.87 | M34: 0.78 | N34: 0.89 | O34: 0.85 | P34: 0.86 | Q34: 0.85 | R34: 0.81
A35: Sorghum (9,8% protein) | B35: Cereal & cereal products | C35: 7 | D35: Pig | E35: Standardized Ileal | F35: 0.657 | G35: 0.73 | H35: 0.68 | I35: 0.74 | J35: 0.76 | K35: 0.69 | L35: 0.77 | M35: 0.68 | N35: 0.76 | O35: 0.71 | P35: 0.73 | Q35: 0.73 | R35: 0.74 | S35: Pocured from Siemer Enterprises Inc
A36: Triticale (Triticum x Secale) | B36: Cereal & cereal products | C36: 2 | D36: Pig | E36: Standardized Ileal | F36: 0.87 | G36: 0.88 | H36: 0.82 | I36: 0.87 | J36: 0.88 | K36: 0.83 | L36: 0.9 | M36: 0.91 | N36: 0.9 | O36: 0.9 | P36: 0.86 | Q36: 0.91 | R36: 0.89
A37: Wheat, durum | B37: Cereal & cereal products | C37: 2 | D37: Pig | E37: Standardized Ileal | F37: 0.855 | G37: 0.88 | H37: 0.83 | I37: 0.89 | J37: 0.9 | K37: 0.81 | L37: 0.89 | M37: 0.91 | N37: 0.91 | O37: 0.9 | P37: 0.86 | Q37: 0.88 | R37: 0.9
A38: Wheat, soft | B38: Cereal & cereal products | C38: 2 | D38: Pig | E38: Standardized Ileal | F38: 0.88 | G38: 0.88 | H38: 0.83 | I38: 0.89 | J38: 0.9 | K38: 0.81 | L38: 0.89 | M38: 0.91 | N38: 0.91 | O38: 0.9 | P38: 0.86 | Q38: 0.88 | R38: 0.9
A39: Wheat flour (fibre < 3,5%) | B39: Cereal & cereal products | C39: 1 | D39: Human(Predicted) | E39: Standardized Ileal | F39: 0.89 | G39: 0.89 | H39: 0.86 | I39: 0.9 | J39: 0.91 | K39: 0.87 | L39: 0.9 | M39: 0.86 | N39: 0.89 | O39: 0.92 | P39: 0.9 | Q39: 0.92 | R39: 0.91
A40: Wheat (11,9% protein) | B40: Cereal & cereal products | C40: 7 | D40: Pig | E40: Standardized Ileal | F40: 0.75 | G40: 0.84 | H40: 0.65 | I40: 0.79 | J40: 0.81 | K40: 0.73 | L40: 0.85 | M40: 0.83 | N40: 0.84 | O40: 0.74 | P40: 0.75 | Q40: 0.87 | R40: 0.84 | S40: Pocured from Siemer Enterprises Inc
...

Sheet Total and digestible IAA
A1: Food item name | B1: Food group | C1: Data source | D1: Data source 2 | E1: Method | F1: Protein | G1: TRP | H1: THR | I1: ILE | J1: LEU | K1: LYS | L1: MET | M1: CYS | N1: PHE | O1: TYR | P1: VAL | Q1: ARG | R1: HIS | S1: Additional information | V1: TRP | W1: THR | X1: ILE | Y1: LEU | Z1: LYS | AA1: MET | AB1: CYS | AC1: PHE | AD1: TYR | AE1: VAL | AF1: HIS | AH1: TRP | AI1: THR | AJ1: ILE | AK1: LEU | AL1: LYS | AM1: SAA | AN1: AAA | AO1: VAL | AP1: HIS | AQ1: Additional information
F2: g/kg | G2: Total IAA g/kg | V2: Digestible IAA g/kg | AH2: Digestible IAA mg/g protein
A3: Barley (not hulless varieties) | B3: Cereal & cereal products | C3: 2 | E3: Standardized Ileal | F3: 113 | G3: 1.4 | H3: 3.9 | I3: 4.1 | J3: 7.7 | K3: 4.3 | L3: 1.9 | M3: 2.6 | N3: 5.5 | O3: 3.2 | P3: 5.7 | Q3: 5.5 | R3: 2.6 | V3: =G3*'IAA digestibility'!G3 -> 1.106 | W3: =H3*'IAA digestibility'!H3 -> 2.925 | X3: =I3*'IAA digestibility'!I3 -> 3.321 | Y3: =J3*'IAA digestibility'!J3 -> 6.391 | Z3: =K3*'IAA digestibility'!K3 -> 3.225 | AA3: =L3*'IAA digestibility'!L3 -> 1.577 | AB3: =M3*'IAA digestibility'!M3 -> 2.184 | AC3: =N3*'IAA digestibility'!N3 -> 4.62 | ... AE3: =P3*'IAA digestibility'!P3 -> 4.56 | AF3: =R3*'IAA digestibility'!R3 -> 2.106 | AH3: =(V3/$F3)*1000 -> 9.7876106 | AI3: =(W3/$F3)*1000 -> 25.884956 | AJ3: =(X3/$F3)*1000 -> 29.389381 | AK3: =(Y3/$F3)*1000 -> 56.557522 | AL3: =(Z3/$F3)*1000 -> 28.539823 | AM3: =((AA3+AB3)/$F3)*1000 -> 33.283186 | AN3: =((AC3+AD3)/$F3)*1000 -> 64.389381 | AO3: =(AE3/$F3)*1000 -> 40.353982 | AP3: =(AF3/$F3)*1000 -> 18.637168
A4: Barley, dehulled (11,8% protein) | B4: Cereal & cereal products | C4: 7 | E4: Standardized Ileal | F4: 118 | G4: 1 | H4: 3.4 | I4: 3.9 | J4: 7.3 | K4: 3.9 | L4: 1.7 | M4: 2.3 | N4: 5.5 | O4: 2.7 | P4: 5.3 | Q4: 5.1 | R4: 2.5 | S4: Pocured from Siemer Enterprises Inc | V4: =G4*'IAA digestibility'!G4 -> 0.84 | W4: =H4*'IAA digestibility'!H4 -> 2.448 | X4: =I4*'IAA digestibility'!I4 -> 2.964 | Y4: =J4*'IAA digestibility'!J4 -> 5.767 | Z4: =K4*'IAA digestibility'!K4 -> 2.886 | AA4: =L4*'IAA digestibility'!L4 -> 1.326 | AB4: =M4*'IAA digestibility'!M4 -> 1.84 | AC4: =N4*'IAA digestibility'!N4 -> 4.51 | ... AE4: =P4*'IAA digestibility'!P4 -> 4.081 | AF4: =R4*'IAA digestibility'!R4 -> 2.025 | AH4: =(V4/$F4)*1000 -> 7.1186441 | AI4: =(W4/$F4)*1000 -> 20.745763 | AJ4: =(X4/$F4)*1000 -> 25.118644 | AK4: =(Y4/$F4)*1000 -> 48.872881 | AL4: =(Z4/$F4)*1000 -> 24.457627 | AM4: =((AA4+AB4)/$F4)*1000 -> 26.830508 | AN4: =((AC4+AD4)/$F4)*1000 -> 55.838983 | AO4: =(AE4/$F4)*1000 -> 34.584746 | AP4: =(AF4/$F4)*1000 -> 17.161017
A5: Biscuits (CP>12%) | B5: Cereal & cereal products | C5: 1,19 | E5: Standardized Ileal | F5: 81 | G5: 0.8 | H5: 2.7 | I5: 2.9 | J5: 5.4 | K5: 2 | L5: 1.2 | M5: 1.7 | N5: 3.7 | O5: 2.3 | P5: 3.7 | Q5: 3.3 | R5: 1.9 | V5: =G5*'IAA digestibility'!G5 -> 0.688 | W5: =H5*'IAA digestibility'!H5 -> 2.457 | X5: =I5*'IAA digestibility'!I5 -> 2.668 | Y5: =J5*'IAA digestibility'!J5 -> 4.914 | Z5: =K5*'IAA digestibility'!K5 -> 1.78 | AA5: =L5*'IAA digestibility'!L5 -> 1.08 | AB5: =M5*'IAA digestibility'!M5 -> 1.479 | AC5: =N5*'IAA digestibility'!N5 -> 3.256 | ... AE5: =P5*'IAA digestibility'!P5 -> 3.33 | AF5: =R5*'IAA digestibility'!R5 -> 1.767 | AH5: =(V5/$F5)*1000 -> 8.4938272 | AI5: =(W5/$F5)*1000 -> 30.333333 | AJ5: =(X5/$F5)*1000 -> 32.938272 | AK5: =(Y5/$F5)*1000 -> 60.666667 | AL5: =(Z5/$F5)*1000 -> 21.975309 | AM5: =((AA5+AB5)/$F5)*1000 -> 31.592593 | AN5: =((AC5+AD5)/$F5)*1000 -> 66.888889 | AO5: =(AE5/$F5)*1000 -> 41.111111 | AP5: =(AF5/$F5)*1000 -> 21.814815
A6: Bread | B6: Cereal & cereal products | C6: 1,19 | E6: Standardized Ileal | F6: 121 | G6: 1.2 | H6: 4 | I6: 4.4 | J6: 8 | K6: 3 | L6: 1.8 | M6: 2.6 | N6: 5.6 | O6: 3.4 | P6: 5.5 | Q6: 5 | R6: 2.9 | V6: =G6*'IAA digestibility'!G6 -> 1.08 | W6: =H6*'IAA digestibility'!H6 -> 3.64 | X6: =I6*'IAA digestibility'!I6 -> 4.048 | Y6: =J6*'IAA digestibility'!J6 -> 7.44 | Z6: =K6*'IAA digestibility'!K6 -> 2.76 | AA6: =L6*'IAA digestibility'!L6 -> 1.674 | AB6: =M6*'IAA digestibility'!M6 -> 2.262 | AC6: =N6*'IAA digestibility'!N6 -> 4.928 | ... AE6: =P6*'IAA digestibility'!P6 -> 5.005 | AF6: =R6*'IAA digestibility'!R6 -> 2.668 | AH6: =(V6/$F6)*1000 -> 8.9256198 | AI6: =(W6/$F6)*1000 -> 30.082645 | AJ6: =(X6/$F6)*1000 -> 33.454545 | AK6: =(Y6/$F6)*1000 -> 61.487603 | AL6: =(Z6/$F6)*1000 -> 22.809917 | AM6: =((AA6+AB6)/$F6)*1000 -> 32.528926 | AN6: =((AC6+AD6)/$F6)*1000 -> 66.859504 | AO6: =(AE6/$F6)*1000 -> 41.363636 | AP6: =(AF6/$F6)*1000 -> 22.049587
A7: Maize flour/Corn flour | B7: Cereal & cereal products | C7: 1 | E7: Standardized Ileal | F7: 76 | G7: 0.5 | H7: 2.7 | I7: 2.6 | J7: 9.2 | K7: 2.2 | L7: 1.6 | M7: 1.7 | N7: 3.7 | O7: 2.8 | P7: 3.7 | Q7: 3.6 | R7: 2.3 | V7: =G7*'IAA digestibility'!G7 -> 0.39 | W7: =H7*'IAA digestibility'!H7 -> 2.052 | X7: =I7*'IAA digestibility'!I7 -> 2.236 | Y7: =J7*'IAA digestibility'!J7 -> 8.464 | Z7: =K7*'IAA digestibility'!K7 -> 1.672 | AA7: =L7*'IAA digestibility'!L7 -> 1.472 | AB7: =M7*'IAA digestibility'!M7 -> 1.343 | AC7: =N7*'IAA digestibility'!N7 -> 3.108 | ... AE7: =P7*'IAA digestibility'!P7 -> 3.145 | AF7: =R7*'IAA digestibility'!R7 -> 1.932 | AH7: =(V7/$F7)*1000 -> 5.1315789 | AI7: =(W7/$F7)*1000 -> 27 | AJ7: =(X7/$F7)*1000 -> 29.421053 | AK7: =(Y7/$F7)*1000 -> 111.36842 | AL7: =(Z7/$F7)*1000 -> 22 | AM7: =((AA7+AB7)/$F7)*1000 -> 37.039474 | AN7: =((AC7+AD7)/$F7)*1000 -> 74.421053 | AO7: =(AE7/$F7)*1000 -> 41.381579 | AP7: =(AF7/$F7)*1000 -> 25.421053
A8: Maize/corn | B8: Cereal & cereal products | C8: 2 | E8: Standardized Ileal | F8: 88 | G8: 0.6 | H8: 3.3 | I8: 3.3 | J8: 10.8 | K8: 2.7 | L8: 1.9 | M8: 2.2 | N8: 4.3 | O8: 3.7 | P8: 4.4 | Q8: 4.2 | R8: 2.6 | V8: =G8*'IAA digestibility'!G8 -> 0.48 | W8: =H8*'IAA digestibility'!H8 -> 2.739 | X8: =I8*'IAA digestibility'!I8 -> 2.904 | Y8: =J8*'IAA digestibility'!J8 -> 10.044 | Z8: =K8*'IAA digestibility'!K8 -> 2.16 | AA8: =L8*'IAA digestibility'!L8 -> 1.729 | AB8: =M8*'IAA digestibility'!M8 -> 1.958 | AC8: =N8*'IAA digestibility'!N8 -> 3.913 | ... AE8: =P8*'IAA digestibility'!P8 -> 3.828 | AF8: =R8*'IAA digestibility'!R8 -> 2.314 | AH8: =(V8/$F8)*1000 -> 5.4545455 | AI8: =(W8/$F8)*1000 -> 31.125 | AJ8: =(X8/$F8)*1000 -> 33 | AK8: =(Y8/$F8)*1000 -> 114.13636 | AL8: =(Z8/$F8)*1000 -> 24.545455 | AM8: =((AA8+AB8)/$F8)*1000 -> 41.897727 | AN8: =((AC8+AD8)/$F8)*1000 -> 82.306818 | AO8: =(AE8/$F8)*1000 -> 43.5 | AP8: =(AF8/$F8)*1000 -> 26.295455
A9: Maize (extruded)/extruded corn | B9: Cereal & cereal products | C9: 2 | E9: Standardized Ileal | F9: 88 | G9: 0.6 | H9: 3.3 | I9: 3.3 | J9: 10.8 | K9: 2.7 | L9: 1.9 | M9: 2.2 | N9: 4.3 | O9: 3.7 | P9: 4.4 | Q9: 4.2 | R9: 2.6 | V9: =G9*'IAA digestibility'!G9 -> 0.498 | W9: =H9*'IAA digestibility'!H9 -> 2.673 | X9: =I9*'IAA digestibility'!I9 -> 2.871 | Y9: =J9*'IAA digestibility'!J9 -> 9.828 | Z9: =K9*'IAA digestibility'!K9 -> 2.133 | AA9: =L9*'IAA digestibility'!L9 -> 1.691 | AB9: =M9*'IAA digestibility'!M9 -> 1.914 | AC9: =N9*'IAA digestibility'!N9 -> 3.87 | ... AE9: =P9*'IAA digestibility'!P9 -> 3.784 | AF9: =R9*'IAA digestibility'!R9 -> 2.262 | AH9: =(V9/$F9)*1000 -> 5.6590909 | AI9: =(W9/$F9)*1000 -> 30.375 | AJ9: =(X9/$F9)*1000 -> 32.625 | AK9: =(Y9/$F9)*1000 -> 111.68182 | AL9: =(Z9/$F9)*1000 -> 24.238636 | AM9: =((AA9+AB9)/$F9)*1000 -> 40.965909 | AN9: =((AC9+AD9)/$F9)*1000 -> 81.397727 | AO9: =(AE9/$F9)*1000 -> 43 | AP9: =(AF9/$F9)*1000 -> 25.704545
A10: Maize (flaked)/flaked corn/rolled corn | B10: Cereal & cereal products | C10: 2 | E10: Standardized Ileal | F10: 88 | G10: 0.6 | H10: 3.3 | I10: 3.3 | J10: 10.8 | K10: 2.7 | L10: 1.9 | M10: 2.2 | N10: 4.3 | O10: 3.7 | P10: 4.4 | Q10: 4.2 | R10: 2.6 | V10: =G10*'IAA digestibility'!G10 -> 0.498 | W10: =H10*'IAA digestibility'!H10 -> 2.673 | X10: =I10*'IAA digestibility'!I10 -> 2.871 | Y10: =J10*'IAA digestibility'!J10 -> 9.828 | Z10: =K10*'IAA digestibility'!K10 -> 2.133 | AA10: =L10*'IAA digestibility'!L10 -> 1.691 | AB10: =M10*'IAA digestibility'!M10 -> 1.914 | AC10: =N10*'IAA digestibility'!N10 -> 3.87 | ... AE10: =P10*'IAA digestibility'!P10 -> 3.784 | AF10: =R10*'IAA digestibility'!R10 -> 2.262 | AH10: =(V10/$F10)*1000 -> 5.6590909 | AI10: =(W10/$F10)*1000 -> 30.375 | AJ10: =(X10/$F10)*1000 -> 32.625 | AK10: =(Y10/$F10)*1000 -> 111.68182 | AL10: =(Z10/$F10)*1000 -> 24.238636 | AM10: =((AA10+AB10)/$F10)*1000 -> 40.965909 | AN10: =((AC10+AD10)/$F10)*1000 -> 81.397727 | AO10: =(AE10/$F10)*1000 -> 43 | AP10: =(AF10/$F10)*1000 -> 25.704545
A11: Maize (high moisure)/humid corn - 60-70% dry matter, raw | B11: Cereal & cereal products | C11: 2 | E11: Standardized Ileal | F11: 92 | G11: 0.6 | H11: 3.4 | I11: 3.4 | J11: 11.4 | K11: 2.8 | L11: 1.9 | M11: 2.3 | N11: 4.5 | O11: 3.9 | P11: 4.6 | Q11: 4.4 | R11: 2.7 | V11: =G11*'IAA digestibility'!G11 -> 0.48 | W11: =H11*'IAA digestibility'!H11 -> 2.822 | X11: =I11*'IAA digestibility'!I11 -> 2.992 | Y11: =J11*'IAA digestibility'!J11 -> 10.602 | Z11: =K11*'IAA digestibility'!K11 -> 2.24 | AA11: =L11*'IAA digestibility'!L11 -> 1.729 | AB11: =M11*'IAA digestibility'!M11 -> 2.024 | AC11: =N11*'IAA digestibility'!N11 -> 4.095 | ... AE11: =P11*'IAA digestibility'!P11 -> 4.002 | AF11: =R11*'IAA digestibility'!R11 -> 2.403 | AH11: =(V11/$F11)*1000 -> 5.2173913 | AI11: =(W11/$F11)*1000 -> 30.673913 | AJ11: =(X11/$F11)*1000 -> 32.521739 | AK11: =(Y11/$F11)*1000 -> 115.23913 | AL11: =(Z11/$F11)*1000 -> 24.347826 | AM11: =((AA11+AB11)/$F11)*1000 -> 40.793478 | AN11: =((AC11+AD11)/$F11)*1000 -> 82.663043 | AO11: =(AE11/$F11)*1000 -> 43.5 | AP11: =(AF11/$F11)*1000 -> 26.119565
A12: Maize bran | B12: Cereal & cereal products | C12: 1 | E12: Standardized Ileal | F12: 94 | G12: 0.7 | H12: 3.5 | I12: 3.3 | J12: 10.5 | K12: 3 | L12: 2 | M12: 2.1 | N12: 4.4 | O12: 3.4 | P12: 4.8 | Q12: 4.7 | R12: 2.7 | V12: =G12*'IAA digestibility'!G12 -> 0.483 | W12: =H12*'IAA digestibility'!H12 -> 2.31 | X12: =I12*'IAA digestibility'!I12 -> 2.541 | Y12: =J12*'IAA digestibility'!J12 -> 8.505 | Z12: =K12*'IAA digestibility'!K12 -> 2.04 | AA12: =L12*'IAA digestibility'!L12 -> 1.66 | AB12: =M12*'IAA digestibility'!M12 -> 1.449 | AC12: =N12*'IAA digestibility'!N12 -> 3.52 | ... AE12: =P12*'IAA digestibility'!P12 -> 3.696 | AF12: =R12*'IAA digestibility'!R12 -> 2.16 | AH12: =(V12/$F12)*1000 -> 5.1382979 | AI12: =(W12/$F12)*1000 -> 24.574468 | AJ12: =(X12/$F12)*1000 -> 27.031915 | AK12: =(Y12/$F12)*1000 -> 90.478723 | AL12: =(Z12/$F12)*1000 -> 21.702128 | AM12: =((AA12+AB12)/$F12)*1000 -> 33.074468 | AN12: =((AC12+AD12)/$F12)*1000 -> 66.382979 | AO12: =(AE12/$F12)*1000 -> 39.319149 | AP12: =(AF12/$F12)*1000 -> 22.978723
A13: Maize, yellow dent (7,5% protein) | B13: Cereal & cereal products | C13: 7 | E13: Standardized Ileal | F13: 75 | G13: 0.5 | H13: 2.3 | I13: 2.3 | J13: 7.1 | K13: 2.3 | L13: 1.4 | M13: 1.4 | N13: 2.9 | O13: 1.9 | P13: 3.2 | Q13: 3.2 | R13: 1.9 | S13: Procured from Exseed Genetics LLC | V13: =G13*'IAA digestibility'!G13 -> 0.35 | W13: =H13*'IAA digestibility'!H13 -> 1.61 | X13: =I13*'IAA digestibility'!I13 -> 1.748 | Y13: =J13*'IAA digestibility'!J13 -> 5.964 | Z13: =K13*'IAA digestibility'!K13 -> 1.725 | AA13: =L13*'IAA digestibility'!L13 -> 1.26 | AB13: =M13*'IAA digestibility'!M13 -> 1.078 | AC13: =N13*'IAA digestibility'!N13 -> 2.407 | ... AE13: =P13*'IAA digestibility'!P13 -> 2.4 | AF13: =R13*'IAA digestibility'!R13 -> 1.577 | AH13: =(V13/$F13)*1000 -> 4.6666667 | AI13: =(W13/$F13)*1000 -> 21.466667 | AJ13: =(X13/$F13)*1000 -> 23.306667 | AK13: =(Y13/$F13)*1000 -> 79.52 | AL13: =(Z13/$F13)*1000 -> 23 | AM13: =((AA13+AB13)/$F13)*1000 -> 31.173333 | AN13: =((AC13+AD13)/$F13)*1000 -> 52.36 | AO13: =(AE13/$F13)*1000 -> 32 | AP13: =(AF13/$F13)*1000 -> 21.026667
A14: Maize, nutridense (8,8% protein) | B14: Cereal & cereal products | C14: 7 | E14: Standardized Ileal | F14: 88 | G14: 0.5 | H14: 2.7 | I14: 3 | J14: 9.6 | K14: 2.9 | L14: 1.7 | M14: 1.7 | N14: 3.9 | O14: 2.4 | P14: 4 | Q14: 4.1 | R14: 2.6 | S14: Procured from Exseed Genetics LLC | V14: =G14*'IAA digestibility'!G14 -> 0.365 | W14: =H14*'IAA digestibility'!H14 -> 2.052 | X14: =I14*'IAA digestibility'!I14 -> 2.43 | Y14: =J14*'IAA digestibility'!J14 -> 8.64 | Z14: =K14*'IAA digestibility'!K14 -> 2.291 | AA14: =L14*'IAA digestibility'!L14 -> 1.547 | AB14: =M14*'IAA digestibility'!M14 -> 1.394 | AC14: =N14*'IAA digestibility'!N14 -> 3.432 | ... AE14: =P14*'IAA digestibility'!P14 -> 3.28 | AF14: =R14*'IAA digestibility'!R14 -> 2.262 | AH14: =(V14/$F14)*1000 -> 4.1477273 | AI14: =(W14/$F14)*1000 -> 23.318182 | AJ14: =(X14/$F14)*1000 -> 27.613636 | AK14: =(Y14/$F14)*1000 -> 98.181818 | AL14: =(Z14/$F14)*1000 -> 26.034091 | AM14: =((AA14+AB14)/$F14)*1000 -> 33.420455 | AN14: =((AC14+AD14)/$F14)*1000 -> 62.181818 | AO14: =(AE14/$F14)*1000 -> 37.272727 | AP14: =(AF14/$F14)*1000 -> 25.704545
A15: Maize, high lysine | B15: Cereal & cereal products | C15: 16 | E15: Standardized Ileal | AQ15: AA composition data not reported
A16: Millet, finger | B16: Cereal & cereal products | C16: 4 | E16: True Ileal | AQ16: AA composition data not reported
A17: Millet, pearl (Penisetum glaucum (l) R. Br)/candle millet/dark millet/bajra/Indian millet/horse millet/bulrush millet/cattail millet | B17: Cereal & cereal products | C17: 2 | E17: Standardized Ileal | F17: 125 | G17: 2.2 | H17: 4.9 | I17: 5.5 | J17: 16.4 | K17: 3.1 | L17: 4.3 | M17: 3 | N17: 6.1 | O17: 3.9 | P17: 6.8 | Q17: 4.9 | R17: 2.9 | V17: =G17*'IAA digestibility'!G17 -> 2.024 | W17: =H17*'IAA digestibility'!H17 -> 4.263 | X17: =I17*'IAA digestibility'!I17 -> 5.005 | Y17: =J17*'IAA digestibility'!J17 -> 14.924 | Z17: =K17*'IAA digestibility'!K17 -> 2.666 | AA17: =L17*'IAA digestibility'!L17 -> 3.612 | AB17: =M17*'IAA digestibility'!M17 -> 2.7 | AC17: =N17*'IAA digestibility'!N17 -> 5.673 | ... AE17: =P17*'IAA digestibility'!P17 -> 6.12 | AF17: =R17*'IAA digestibility'!R17 -> 2.668 | AH17: =(V17/$F17)*1000 -> 16.192 | AI17: =(W17/$F17)*1000 -> 34.104 | AJ17: =(X17/$F17)*1000 -> 40.04 | AK17: =(Y17/$F17)*1000 -> 119.392 | AL17: =(Z17/$F17)*1000 -> 21.328 | AM17: =((AA17+AB17)/$F17)*1000 -> 50.496 | AN17: =((AC17+AD17)/$F17)*1000 -> 72.528 | AO17: =(AE17/$F17)*1000 -> 48.96 | AP17: =(AF17/$F17)*1000 -> 21.344
A18: Millet, proso (Panicum miliaceum L.)/common millet/broomtail millet/hog millet/white millet/broomcorn millet | B18: Cereal & cereal products | C18: 2 | E18: Standardized Ileal | F18: 142 | G18: 2.6 | H18: 5.4 | I18: 6.4 | J18: 19 | K18: 3.2 | L18: 5 | M18: 3.3 | N18: 7 | O18: 4.4 | P18: 7.7 | Q18: 5.3 | R18: 3.1 | V18: =G18*'IAA digestibility'!G18 -> 2.002 | W18: =H18*'IAA digestibility'!H18 -> 4.104 | X18: =I18*'IAA digestibility'!I18 -> 5.184 | Y18: =J18*'IAA digestibility'!J18 -> 15.77 | Z18: =K18*'IAA digestibility'!K18 -> 2.464 | AA18: =L18*'IAA digestibility'!L18 -> 4.2 | AB18: =M18*'IAA digestibility'!M18 -> 2.475 | AC18: =N18*'IAA digestibility'!N18 -> 5.88 | ... AE18: =P18*'IAA digestibility'!P18 -> 6.083 | AF18: =R18*'IAA digestibility'!R18 -> 2.542 | AH18: =(V18/$F18)*1000 -> 14.098592 | AI18: =(W18/$F18)*1000 -> 28.901408 | AJ18: =(X18/$F18)*1000 -> 36.507042 | AK18: =(Y18/$F18)*1000 -> 111.05634 | AL18: =(Z18/$F18)*1000 -> 17.352113 | AM18: =((AA18+AB18)/$F18)*1000 -> 47.007042 | AN18: =((AC18+AD18)/$F18)*1000 -> 66.816901 | AO18: =(AE18/$F18)*1000 -> 42.838028 | AP18: =(AF18/$F18)*1000 -> 17.901408
A19: Oat groats (Avena sativa L.)/oat grain from whuch hulls have been removed | B19: Cereal & cereal products | C19: 2 | E19: Standardized Ileal | F19: 128 | G19: 1.6 | H19: 4.5 | I19: 4.9 | J19: 9.4 | K19: 5.3 | L19: 2.2 | M19: 4 | N19: 6.5 | O19: 4.6 | P19: 6.8 | Q19: 8.8 | R19: 2.8 | V19: =G19*'IAA digestibility'!G19 -> 1.312 | W19: =H19*'IAA digestibility'!H19 -> 3.6 | X19: =I19*'IAA digestibility'!I19 -> 4.067 | Y19: =J19*'IAA digestibility'!J19 -> 7.802 | Z19: =K19*'IAA digestibility'!K19 -> 4.187 | AA19: =L19*'IAA digestibility'!L19 -> 1.87 | AB19: =M19*'IAA digestibility'!M19 -> 3.4 | AC19: =N19*'IAA digestibility'!N19 -> 5.395 | ... AE19: =P19*'IAA digestibility'!P19 -> 5.508 | AF19: =R19*'IAA digestibility'!R19 -> 2.324 | AH19: =(V19/$F19)*1000 -> 10.25 | AI19: =(W19/$F19)*1000 -> 28.125 | AJ19: =(X19/$F19)*1000 -> 31.773438 | AK19: =(Y19/$F19)*1000 -> 60.953125 | AL19: =(Z19/$F19)*1000 -> 32.710938 | AM19: =((AA19+AB19)/$F19)*1000 -> 41.171875 | AN19: =((AC19+AD19)/$F19)*1000 -> 72.695312 | AO19: =(AE19/$F19)*1000 -> 43.03125 | AP19: =(AF19/$F19)*1000 -> 18.15625
A20: Oats (Avena sativa L.) | B20: Cereal & cereal products | C20: 1,19 | E20: Standardized Ileal | F20: 102 | G20: 1.2 | H20: 3.6 | I20: 3.8 | J20: 7.5 | K20: 4.2 | L20: 1.7 | M20: 3.1 | N20: 4.9 | O20: 3.4 | P20: 5.3 | Q20: 6.6 | R20: 2.2 | V20: =G20*'IAA digestibility'!G20 -> 0.924 | W20: =H20*'IAA digestibility'!H20 -> 2.52 | X20: =I20*'IAA digestibility'!I20 -> 3.04 | Y20: =J20*'IAA digestibility'!J20 -> 6.15 | Z20: =K20*'IAA digestibility'!K20 -> 3.192 | AA20: =L20*'IAA digestibility'!L20 -> 1.394 | AB20: =M20*'IAA digestibility'!M20 -> 2.232 | AC20: =N20*'IAA digestibility'!N20 -> 4.116 | ... AE20: =P20*'IAA digestibility'!P20 -> 4.187 | AF20: =R20*'IAA digestibility'!R20 -> 1.87 | AH20: =(V20/$F20)*1000 -> 9.0588235 | AI20: =(W20/$F20)*1000 -> 24.705882 | AJ20: =(X20/$F20)*1000 -> 29.803922 | AK20: =(Y20/$F20)*1000 -> 60.294118 | AL20: =(Z20/$F20)*1000 -> 31.294118 | AM20: =((AA20+AB20)/$F20)*1000 -> 35.54902 | AN20: =((AC20+AD20)/$F20)*1000 -> 67.352941 | AO20: =(AE20/$F20)*1000 -> 41.04902 | AP20: =(AF20/$F20)*1000 -> 18.333333
A21: Oats (Avena sativa L.) | B21: Cereal & cereal products | C21: 2 | E21: Standardized Ileal | F21: 108 | G21: 1.4 | H21: 3.8 | I21: 4.1 | J21: 7.9 | K21: 4.5 | L21: 1.9 | M21: 3.6 | N21: 5.4 | O21: 3.8 | P21: 5.7 | Q21: 7.2 | R21: 2.3 | V21: =G21*'IAA digestibility'!G21 -> 1.092 | W21: =H21*'IAA digestibility'!H21 -> 2.622 | X21: =I21*'IAA digestibility'!I21 -> 3.239 | Y21: =J21*'IAA digestibility'!J21 -> 6.399 | Z21: =K21*'IAA digestibility'!K21 -> 3.285 | AA21: =L21*'IAA digestibility'!L21 -> 1.596 | AB21: =M21*'IAA digestibility'!M21 -> 2.7 | AC21: =N21*'IAA digestibility'!N21 -> 4.536 | ... AE21: =P21*'IAA digestibility'!P21 -> 4.389 | AF21: =R21*'IAA digestibility'!R21 -> 1.909 | AH21: =(V21/$F21)*1000 -> 10.111111 | AI21: =(W21/$F21)*1000 -> 24.277778 | AJ21: =(X21/$F21)*1000 -> 29.990741 | AK21: =(Y21/$F21)*1000 -> 59.25 | AL21: =(Z21/$F21)*1000 -> 30.416667 | AM21: =((AA21+AB21)/$F21)*1000 -> 39.777778 | AN21: =((AC21+AD21)/$F21)*1000 -> 70.148148 | AO21: =(AE21/$F21)*1000 -> 40.638889 | AP21: =(AF21/$F21)*1000 -> 17.675926
A22: Oats, flaked/flaked or rolled oat grain | B22: Cereal & cereal products | C22: 2 | E22: Standardized Ileal | F22: 108 | G22: 1.4 | H22: 3.8 | I22: 4.1 | J22: 7.9 | K22: 4.5 | L22: 1.9 | M22: 3.6 | N22: 5.4 | O22: 3.8 | P22: 5.7 | Q22: 7.2 | R22: 2.3 | V22: =G22*'IAA digestibility'!G22 -> 1.092 | W22: =H22*'IAA digestibility'!H22 -> 2.622 | X22: =I22*'IAA digestibility'!I22 -> 3.239 | Y22: =J22*'IAA digestibility'!J22 -> 6.399 | Z22: =K22*'IAA digestibility'!K22 -> 3.285 | AA22: =L22*'IAA digestibility'!L22 -> 1.596 | AB22: =M22*'IAA digestibility'!M22 -> 2.7 | AC22: =N22*'IAA digestibility'!N22 -> 5.022 | ... AE22: =P22*'IAA digestibility'!P22 -> 4.389 | AF22: =R22*'IAA digestibility'!R22 -> 1.909 | AH22: =(V22/$F22)*1000 -> 10.111111 | AI22: =(W22/$F22)*1000 -> 24.277778 | AJ22: =(X22/$F22)*1000 -> 29.990741 | AK22: =(Y22/$F22)*1000 -> 59.25 | AL22: =(Z22/$F22)*1000 -> 30.416667 | AM22: =((AA22+AB22)/$F22)*1000 -> 39.777778 | AN22: =((AC22+AD22)/$F22)*1000 -> 74.296296 | AO22: =(AE22/$F22)*1000 -> 40.638889 | AP22: =(AF22/$F22)*1000 -> 17.675926
A23: Oats, dehulled (13,1% protein) | B23: Cereal & cereal products | C23: 7 | E23: Standardized Ileal | F23: 131 | G23: 1 | H23: 4.3 | I23: 5.1 | J23: 9.8 | K23: 5.7 | L23: 2.3 | M23: 4 | N23: 6.6 | O23: 3.8 | P23: 7.1 | Q23: 8.7 | R23: 3.2 | S23: Pocured from Siemer Enterprises Inc | V23: =G23*'IAA digestibility'!G23 -> 0.82 | W23: =H23*'IAA digestibility'!H23 -> 3.483 | X23: =I23*'IAA digestibility'!I23 -> 4.437 | Y23: =J23*'IAA digestibility'!J23 -> 8.526 | Z23: =K23*'IAA digestibility'!K23 -> 4.902 | AA23: =L23*'IAA digestibility'!L23 -> 2.07 | AB23: =M23*'IAA digestibility'!M23 -> 3.08 | AC23: =N23*'IAA digestibility'!N23 -> 5.808 | ... AE23: =P23*'IAA digestibility'!P23 -> 6.035 | AF23: =R23*'IAA digestibility'!R23 -> 2.816 | AH23: =(V23/$F23)*1000 -> 6.259542 | AI23: =(W23/$F23)*1000 -> 26.587786 | AJ23: =(X23/$F23)*1000 -> 33.870229 | AK23: =(Y23/$F23)*1000 -> 65.083969 | AL23: =(Z23/$F23)*1000 -> 37.419847 | AM23: =((AA23+AB23)/$F23)*1000 -> 39.312977 | AN23: =((AC23+AD23)/$F23)*1000 -> 67.832061 | AO23: =(AE23/$F23)*1000 -> 46.068702 | AP23: =(AF23/$F23)*1000 -> 21.496183
A24: Rice | B24: Cereal & cereal products | C24: 1,19 | E24: True Ileal | F24: 78 | G24: 0.9 | H24: 2.9 | I24: 2.9 | J24: 5.7 | K24: 3.3 | L24: 1.6 | M24: 1.7 | N24: 3.7 | O24: 2.7 | P24: 4.3 | Q24: 6.1 | R24: 2.1 | V24: =G24*'IAA digestibility'!G24 -> 0.801 | W24: =H24*'IAA digestibility'!H24 -> 2.378 | X24: =I24*'IAA digestibility'!I24 -> 2.175 | Y24: =J24*'IAA digestibility'!J24 -> 4.617 | Z24: =K24*'IAA digestibility'!K24 -> 3.036 | AA24: =L24*'IAA digestibility'!L24 -> 1.376 | AB24: =M24*'IAA digestibility'!M24 -> 1.649 | AC24: =N24*'IAA digestibility'!N24 -> 3.182 | ... AE24: =P24*'IAA digestibility'!P24 -> 3.784 | AF24: =R24*'IAA digestibility'!R24 -> 2.079 | AH24: =(V24/$F24)*1000 -> 10.269231 | AI24: =(W24/$F24)*1000 -> 30.487179 | AJ24: =(X24/$F24)*1000 -> 27.884615 | AK24: =(Y24/$F24)*1000 -> 59.192308 | AL24: =(Z24/$F24)*1000 -> 38.923077 | AM24: =((AA24+AB24)/$F24)*1000 -> 38.782051 | AN24: =((AC24+AD24)/$F24)*1000 -> 68.141026 | AO24: =(AE24/$F24)*1000 -> 48.512821 | AP24: =(AF24/$F24)*1000 -> 26.653846
A25: Rice, brown (Oryza sativa L.)/unpolished rice without the hulls but with the outer grain layers | B25: Cereal & cereal products | C25: 2 | E25: Standardized Ileal | F25: 105 | G25: 1.8 | H25: 3.8 | I25: 4.7 | J25: 8.4 | K25: 3.9 | L25: 2.4 | M25: 1.7 | N25: 5.5 | O25: 4.4 | P25: 6.1 | Q25: 8.4 | R25: 2.4 | V25: =G25*'IAA digestibility'!G25 -> 1.53 | W25: =H25*'IAA digestibility'!H25 -> 3.192 | X25: =I25*'IAA digestibility'!I25 -> 4.042 | Y25: =J25*'IAA digestibility'!J25 -> 7.392 | Z25: =K25*'IAA digestibility'!K25 -> 3.354 | AA25: =L25*'IAA digestibility'!L25 -> 2.136 | AB25: =M25*'IAA digestibility'!M25 -> 1.445 | AC25: =N25*'IAA digestibility'!N25 -> 4.895 | ... AE25: =P25*'IAA digestibility'!P25 -> 5.246 | AF25: =R25*'IAA digestibility'!R25 -> 2.112 | AH25: =(V25/$F25)*1000 -> 14.571429 | AI25: =(W25/$F25)*1000 -> 30.4 | AJ25: =(X25/$F25)*1000 -> 38.495238 | AK25: =(Y25/$F25)*1000 -> 70.4 | AL25: =(Z25/$F25)*1000 -> 31.942857 | AM25: =((AA25+AB25)/$F25)*1000 -> 34.104762 | AN25: =((AC25+AD25)/$F25)*1000 -> 83.495238 | AO25: =(AE25/$F25)*1000 -> 49.961905 | AP25: =(AF25/$F25)*1000 -> 20.114286
A26: Rice, paddy/whole rice grain with the hulls included | B26: Cereal & cereal products | C26: 2 | E26: Standardized Ileal | F26: 85 | G26: 1.5 | H26: 3.1 | I26: 3.8 | J26: 6.7 | K26: 3.2 | L26: 2.1 | M26: 1.6 | N26: 4.3 | O26: 3.6 | P26: 5 | Q26: 6.7 | R26: 1.9 | V26: =G26*'IAA digestibility'!G26 -> 1.14 | W26: =H26*'IAA digestibility'!H26 -> 2.325 | X26: =I26*'IAA digestibility'!I26 -> 3.04 | Y26: =J26*'IAA digestibility'!J26 -> 5.494 | Z26: =K26*'IAA digestibility'!K26 -> 2.4 | AA26: =L26*'IAA digestibility'!L26 -> 1.743 | AB26: =M26*'IAA digestibility'!M26 -> 1.168 | AC26: =N26*'IAA digestibility'!N26 -> 3.569 | ... AE26: =P26*'IAA digestibility'!P26 -> 3.9 | AF26: =R26*'IAA digestibility'!R26 -> 1.52 | AH26: =(V26/$F26)*1000 -> 13.411765 | AI26: =(W26/$F26)*1000 -> 27.352941 | AJ26: =(X26/$F26)*1000 -> 35.764706 | AK26: =(Y26/$F26)*1000 -> 64.635294 | AL26: =(Z26/$F26)*1000 -> 28.235294 | AM26: =((AA26+AB26)/$F26)*1000 -> 34.247059 | AN26: =((AC26+AD26)/$F26)*1000 -> 76.294118 | AO26: =(AE26/$F26)*1000 -> 45.882353 | AP26: =(AF26/$F26)*1000 -> 17.882353
A27: Rice, polished, broken (byproduct of the polishing process consisting of small or broken grains) | B27: Cereal & cereal products | C27: 2 | E27: Standardized Ileal | F27: 92 | G27: 1.6 | H27: 3.3 | I27: 4.1 | J27: 7.3 | K27: 3.5 | L27: 2.2 | M27: 1.6 | N27: 4.7 | O27: 3.9 | P27: 5.4 | Q27: 7.3 | R27: 2.1 | V27: =G27*'IAA digestibility'!G27 -> 1.52 | W27: =H27*'IAA digestibility'!H27 -> 3.102 | X27: =I27*'IAA digestibility'!I27 -> 3.854 | Y27: =J27*'IAA digestibility'!J27 -> 6.935 | Z27: =K27*'IAA digestibility'!K27 -> 3.29 | AA27: =L27*'IAA digestibility'!L27 -> 2.068 | AB27: =M27*'IAA digestibility'!M27 -> 1.504 | AC27: =N27*'IAA digestibility'!N27 -> 4.418 | ... AE27: =P27*'IAA digestibility'!P27 -> 5.13 | AF27: =R27*'IAA digestibility'!R27 -> 1.974 | AH27: =(V27/$F27)*1000 -> 16.521739 | AI27: =(W27/$F27)*1000 -> 33.717391 | AJ27: =(X27/$F27)*1000 -> 41.891304 | AK27: =(Y27/$F27)*1000 -> 75.380435 | AL27: =(Z27/$F27)*1000 -> 35.76087 | AM27: =((AA27+AB27)/$F27)*1000 -> 38.826087 | AN27: =((AC27+AD27)/$F27)*1000 -> 82.782609 | AO27: =(AE27/$F27)*1000 -> 55.76087 | AP27: =(AF27/$F27)*1000 -> 21.456522
A28: Rice, white, polished (9,0% protein) | B28: Cereal & cereal products | C28: 7 | E28: Standardized Ileal | F28: 90 | G28: 0.7 | H28: 2.7 | I28: 3.5 | J28: 6.6 | K28: 3 | L28: 2.1 | M28: 1.9 | N28: 4.2 | O28: 2.3 | P28: 4.9 | Q28: 6.1 | R28: 2.1 | S28: Procured from Walmart | V28: =G28*'IAA digestibility'!G28 -> 0.665 | W28: =H28*'IAA digestibility'!H28 -> 2.457 | X28: =I28*'IAA digestibility'!I28 -> 3.22 | Y28: =J28*'IAA digestibility'!J28 -> 6.204 | Z28: =K28*'IAA digestibility'!K28 -> 2.76 | AA28: =L28*'IAA digestibility'!L28 -> 1.995 | AB28: =M28*'IAA digestibility'!M28 -> 1.786 | AC28: =N28*'IAA digestibility'!N28 -> 3.99 | ... AE28: =P28*'IAA digestibility'!P28 -> 4.606 | AF28: =R28*'IAA digestibility'!R28 -> 1.911 | AH28: =(V28/$F28)*1000 -> 7.3888889 | AI28: =(W28/$F28)*1000 -> 27.3 | AJ28: =(X28/$F28)*1000 -> 35.777778 | AK28: =(Y28/$F28)*1000 -> 68.933333 | AL28: =(Z28/$F28)*1000 -> 30.666667 | AM28: =((AA28+AB28)/$F28)*1000 -> 42.011111 | AN28: =((AC28+AD28)/$F28)*1000 -> 67.844444 | AO28: =(AE28/$F28)*1000 -> 51.177778 | AP28: =(AF28/$F28)*1000 -> 21.233333
A29: Rice bran | B29: Cereal & cereal products | C29: 1,19 | E29: Standardized Ileal | F29: 143 | G29: 1.6 | H29: 5.3 | I29: 5.3 | J29: 10.4 | K29: 6 | L29: 3 | M29: 3.1 | N29: 6.7 | O29: 4.9 | P29: 7.9 | Q29: 11.1 | R29: 3.9 | V29: =G29*'IAA digestibility'!G29 -> 1.152 | W29: =H29*'IAA digestibility'!H29 -> 3.392 | X29: =I29*'IAA digestibility'!I29 -> 3.551 | Y29: =J29*'IAA digestibility'!J29 -> 6.968 | Z29: =K29*'IAA digestibility'!K29 -> 4.14 | AA29: =L29*'IAA digestibility'!L29 -> 2.19 | AB29: =M29*'IAA digestibility'!M29 -> 2.015 | AC29: =N29*'IAA digestibility'!N29 -> 4.556 | ... AE29: =P29*'IAA digestibility'!P29 -> 5.214 | AF29: =R29*'IAA digestibility'!R29 -> 3.003 | AH29: =(V29/$F29)*1000 -> 8.0559441 | AI29: =(W29/$F29)*1000 -> 23.72028 | AJ29: =(X29/$F29)*1000 -> 24.832168 | AK29: =(Y29/$F29)*1000 -> 48.727273 | AL29: =(Z29/$F29)*1000 -> 28.951049 | AM29: =((AA29+AB29)/$F29)*1000 -> 29.405594 | AN29: =((AC29+AD29)/$F29)*1000 -> 58.93007 | AO29: =(AE29/$F29)*1000 -> 36.461538 | AP29: =(AF29/$F29)*1000 -> 21
A30: Rye (Secale cereale L.) | B30: Cereal & cereal products | C30: 2 | E30: Standardized Ileal | F30: 98 | G30: 0.9 | H30: 3.4 | I30: 3.4 | J30: 6 | K30: 3.9 | L30: 1.6 | M30: 2.3 | N30: 4.3 | O30: 2.5 | P30: 4.8 | Q30: 5 | R30: 2.1 | V30: =G30*'IAA digestibility'!G30 -> 0.684 | W30: =H30*'IAA digestibility'!H30 -> 2.414 | X30: =I30*'IAA digestibility'!I30 -> 2.618 | Y30: =J30*'IAA digestibility'!J30 -> 4.68 | Z30: =K30*'IAA digestibility'!K30 -> 2.808 | AA30: =L30*'IAA digestibility'!L30 -> 1.296 | AB30: =M30*'IAA digestibility'!M30 -> 1.932 | AC30: =N30*'IAA digestibility'!N30 -> 3.526 | ... AE30: =P30*'IAA digestibility'!P30 -> 3.6 | AF30: =R30*'IAA digestibility'!R30 -> 1.659 | AH30: =(V30/$F30)*1000 -> 6.9795918 | AI30: =(W30/$F30)*1000 -> 24.632653 | AJ30: =(X30/$F30)*1000 -> 26.714286 | AK30: =(Y30/$F30)*1000 -> 47.755102 | AL30: =(Z30/$F30)*1000 -> 28.653061 | AM30: =((AA30+AB30)/$F30)*1000 -> 32.938776 | AN30: =((AC30+AD30)/$F30)*1000 -> 55.622449 | AO30: =(AE30/$F30)*1000 -> 36.734694 | AP30: =(AF30/$F30)*1000 -> 16.928571
A31: Rye (12,1% protein) | B31: Cereal & cereal products | C31: 7 | E31: Standardized Ileal | F31: 121 | G31: 0.9 | H31: 3.3 | I31: 3.8 | J31: 6.7 | K31: 4.1 | L31: 1.7 | M31: 2.2 | N31: 4.9 | O31: 2.2 | P31: 5.1 | Q31: 5.3 | R31: 2.6 | S31: Pocured from Siemer Enterprises Inc | V31: =G31*'IAA digestibility'!G31 -> 0.675 | W31: =H31*'IAA digestibility'!H31 -> 2.112 | X31: =I31*'IAA digestibility'!I31 -> 2.736 | Y31: =J31*'IAA digestibility'!J31 -> 4.958 | Z31: =K31*'IAA digestibility'!K31 -> 2.747 | AA31: =L31*'IAA digestibility'!L31 -> 1.36 | AB31: =M31*'IAA digestibility'!M31 -> 1.672 | AC31: =N31*'IAA digestibility'!N31 -> 3.871 | ... AE31: =P31*'IAA digestibility'!P31 -> 3.621 | AF31: =R31*'IAA digestibility'!R31 -> 2.002 | AH31: =(V31/$F31)*1000 -> 5.5785124 | AI31: =(W31/$F31)*1000 -> 17.454545 | AJ31: =(X31/$F31)*1000 -> 22.61157 | AK31: =(Y31/$F31)*1000 -> 40.975207 | AL31: =(Z31/$F31)*1000 -> 22.702479 | AM31: =((AA31+AB31)/$F31)*1000 -> 25.057851 | AN31: =((AC31+AD31)/$F31)*1000 -> 43.991736 | AO31: =(AE31/$F31)*1000 -> 29.92562 | AP31: =(AF31/$F31)*1000 -> 16.545455
A32: Seitan (wheat based protein), 20,9 g/100 g protein) | B32: Cereal & cereal products | C32: 8 | E32: Standardized Ileal | F32: 209.3 | G32: 5.7 | H32: 4.6 | I32: 7.6 | J32: 14.2 | K32: 2.9 | L32: 3.9 | M32: 4 | N32: 10.3 | O32: 4.9 | P32: 7.8 | Q32: 2.6 | R32: 4.7 | S32: Commercial origin | V32: =G32*'IAA digestibility'!G32 -> 5.2554 | W32: =H32*'IAA digestibility'!H32 -> 4.3286 | X32: =I32*'IAA digestibility'!I32 -> 7.3036 | Y32: =J32*'IAA digestibility'!J32 -> 13.6888 | Z32: =K32*'IAA digestibility'!K32 -> 2.8362 | AA32: =L32*'IAA digestibility'!L32 -> 3.8142 | AB32: =M32*'IAA digestibility'!M32 -> 3.96 | AC32: =N32*'IAA digestibility'!N32 -> 10.2897 | ... AE32: =P32*'IAA digestibility'!P32 -> 7.5504 | AF32: =R32*'IAA digestibility'!R32 -> 4.4932 | AH32: =(V32/$F32)*1000 -> 25.109412 | AI32: =(W32/$F32)*1000 -> 20.681319 | AJ32: =(X32/$F32)*1000 -> 34.895366 | AK32: =(Y32/$F32)*1000 -> 65.402771 | AL32: =(Z32/$F32)*1000 -> 13.550884 | AM32: =((AA32+AB32)/$F32)*1000 -> 37.143813 | AN32: =((AC32+AD32)/$F32)*1000 -> 71.262781 | AO32: =(AE32/$F32)*1000 -> 36.074534 | AP32: =(AF32/$F32)*1000 -> 21.46775
A33: Sorghum (Sorghum bicolor (L) Moench, low tannin variety | B33: Cereal & cereal products | C33: 2 | E33: Standardized Ileal | F33: 106 | G33: 1.1 | H33: 3.5 | I33: 4.5 | J33: 14.4 | K33: 2.5 | L33: 1.8 | M33: 2 | N33: 5.7 | O33: 4.3 | P33: 5.8 | Q33: 4.3 | R33: 2.4 | V33: =G33*'IAA digestibility'!G33 -> 0.869 | W33: =H33*'IAA digestibility'!H33 -> 2.66 | X33: =I33*'IAA digestibility'!I33 -> 3.735 | Y33: =J33*'IAA digestibility'!J33 -> 12.384 | Z33: =K33*'IAA digestibility'!K33 -> 1.85 | AA33: =L33*'IAA digestibility'!L33 -> 1.53 | AB33: =M33*'IAA digestibility'!M33 -> 1.54 | AC33: =N33*'IAA digestibility'!N33 -> 4.845 | ... AE33: =P33*'IAA digestibility'!P33 -> 4.698 | AF33: =R33*'IAA digestibility'!R33 -> 1.872 | AH33: =(V33/$F33)*1000 -> 8.1981132 | AI33: =(W33/$F33)*1000 -> 25.09434 | AJ33: =(X33/$F33)*1000 -> 35.235849 | AK33: =(Y33/$F33)*1000 -> 116.83019 | AL33: =(Z33/$F33)*1000 -> 17.45283 | AM33: =((AA33+AB33)/$F33)*1000 -> 28.962264 | AN33: =((AC33+AD33)/$F33)*1000 -> 80.188679 | AO33: =(AE33/$F33)*1000 -> 44.320755 | AP33: =(AF33/$F33)*1000 -> 17.660377
A34: Sorghum (Sorghum bicolor (L) Moench, low tannin variety | B34: Cereal & cereal products | C34: 1,19 | E34: Standardized Ileal | F34: 87 | G34: 1 | H34: 2.9 | I34: 3.5 | J34: 11.3 | K34: 2.1 | L34: 1.6 | M34: 1.6 | N34: 4.6 | O34: 3.4 | P34: 4.3 | Q34: 3.5 | R34: 2.1 | V34: =G34*'IAA digestibility'!G34 -> 0.87 | W34: =H34*'IAA digestibility'!H34 -> 2.436 | X34: =I34*'IAA digestibility'!I34 -> 3.045 | Y34: =J34*'IAA digestibility'!J34 -> 9.944 | Z34: =K34*'IAA digestibility'!K34 -> 1.659 | AA34: =L34*'IAA digestibility'!L34 -> 1.392 | AB34: =M34*'IAA digestibility'!M34 -> 1.248 | AC34: =N34*'IAA digestibility'!N34 -> 4.094 | ... AE34: =P34*'IAA digestibility'!P34 -> 3.698 | AF34: =R34*'IAA digestibility'!R34 -> 1.701 | AH34: =(V34/$F34)*1000 -> 10 | AI34: =(W34/$F34)*1000 -> 28 | AJ34: =(X34/$F34)*1000 -> 35 | AK34: =(Y34/$F34)*1000 -> 114.29885 | AL34: =(Z34/$F34)*1000 -> 19.068966 | AM34: =((AA34+AB34)/$F34)*1000 -> 30.344828 | AN34: =((AC34+AD34)/$F34)*1000 -> 80.275862 | AO34: =(AE34/$F34)*1000 -> 42.505747 | AP34: =(AF34/$F34)*1000 -> 19.551724
A35: Sorghum (9,8% protein) | B35: Cereal & cereal products | C35: 7 | E35: Standardized Ileal | F35: 98 | G35: 0.5 | H35: 2.9 | I35: 3.7 | J35: 12.4 | K35: 2 | L35: 1.5 | M35: 1.5 | N35: 4.7 | O35: 3 | P35: 4.6 | Q35: 3.3 | R35: 2.2 | S35: Pocured from Siemer Enterprises Inc | V35: =G35*'IAA digestibility'!G35 -> 0.365 | W35: =H35*'IAA digestibility'!H35 -> 1.972 | X35: =I35*'IAA digestibility'!I35 -> 2.738 | Y35: =J35*'IAA digestibility'!J35 -> 9.424 | Z35: =K35*'IAA digestibility'!K35 -> 1.38 | AA35: =L35*'IAA digestibility'!L35 -> 1.155 | AB35: =M35*'IAA digestibility'!M35 -> 1.02 | AC35: =N35*'IAA digestibility'!N35 -> 3.572 | ... AE35: =P35*'IAA digestibility'!P35 -> 3.358 | AF35: =R35*'IAA digestibility'!R35 -> 1.628 | AH35: =(V35/$F35)*1000 -> 3.7244898 | AI35: =(W35/$F35)*1000 -> 20.122449 | AJ35: =(X35/$F35)*1000 -> 27.938776 | AK35: =(Y35/$F35)*1000 -> 96.163265 | AL35: =(Z35/$F35)*1000 -> 14.081633 | AM35: =((AA35+AB35)/$F35)*1000 -> 22.193878 | AN35: =((AC35+AD35)/$F35)*1000 -> 58.183673 | AO35: =(AE35/$F35)*1000 -> 34.265306 | AP35: =(AF35/$F35)*1000 -> 16.612245
A36: Triticale (Triticum x Secale) | B36: Cereal & cereal products | C36: 2 | E36: Standardized Ileal | F36: 115 | G36: 1.4 | H36: 3.8 | I36: 4.4 | J36: 7.3 | K36: 4.5 | L36: 2 | M36: 3 | N36: 5 | O36: 3.5 | P36: 5.5 | Q36: 6.1 | R36: 2.7 | V36: =G36*'IAA digestibility'!G36 -> 1.232 | W36: =H36*'IAA digestibility'!H36 -> 3.116 | X36: =I36*'IAA digestibility'!I36 -> 3.828 | Y36: =J36*'IAA digestibility'!J36 -> 6.424 | Z36: =K36*'IAA digestibility'!K36 -> 3.735 | AA36: =L36*'IAA digestibility'!L36 -> 1.8 | AB36: =M36*'IAA digestibility'!M36 -> 2.73 | AC36: =N36*'IAA digestibility'!N36 -> 4.5 | ... AE36: =P36*'IAA digestibility'!P36 -> 4.73 | AF36: =R36*'IAA digestibility'!R36 -> 2.403 | AH36: =(V36/$F36)*1000 -> 10.713043 | AI36: =(W36/$F36)*1000 -> 27.095652 | AJ36: =(X36/$F36)*1000 -> 33.286957 | AK36: =(Y36/$F36)*1000 -> 55.86087 | AL36: =(Z36/$F36)*1000 -> 32.478261 | AM36: =((AA36+AB36)/$F36)*1000 -> 39.391304 | AN36: =((AC36+AD36)/$F36)*1000 -> 66.521739 | AO36: =(AE36/$F36)*1000 -> 41.130435 | AP36: =(AF36/$F36)*1000 -> 20.895652
A37: Wheat, durum | B37: Cereal & cereal products | C37: 2 | E37: Standardized Ileal | F37: 164 | G37: 1.8 | H37: 4.8 | I37: 5.9 | J37: 11.1 | K37: 4.3 | L37: 2.6 | M37: 3.6 | N37: 8 | O37: 5.2 | P37: 7.1 | Q37: 7.9 | R37: 3.7 | V37: =G37*'IAA digestibility'!G37 -> 1.584 | W37: =H37*'IAA digestibility'!H37 -> 3.984 | X37: =I37*'IAA digestibility'!I37 -> 5.251 | Y37: =J37*'IAA digestibility'!J37 -> 9.99 | Z37: =K37*'IAA digestibility'!K37 -> 3.483 | AA37: =L37*'IAA digestibility'!L37 -> 2.314 | AB37: =M37*'IAA digestibility'!M37 -> 3.276 | AC37: =N37*'IAA digestibility'!N37 -> 7.28 | ... AE37: =P37*'IAA digestibility'!P37 -> 6.106 | AF37: =R37*'IAA digestibility'!R37 -> 3.33 | AH37: =(V37/$F37)*1000 -> 9.6585366 | AI37: =(W37/$F37)*1000 -> 24.292683 | AJ37: =(X37/$F37)*1000 -> 32.018293 | AK37: =(Y37/$F37)*1000 -> 60.914634 | AL37: =(Z37/$F37)*1000 -> 21.237805 | AM37: =((AA37+AB37)/$F37)*1000 -> 34.085366 | AN37: =((AC37+AD37)/$F37)*1000 -> 72.926829 | AO37: =(AE37/$F37)*1000 -> 37.231707 | AP37: =(AF37/$F37)*1000 -> 20.304878
A38: Wheat, soft | B38: Cereal & cereal products | C38: 2 | E38: Standardized Ileal | F38: 126 | G38: 1.5 | H38: 3.8 | I38: 4.5 | J38: 8.5 | K38: 3.6 | L38: 2 | M38: 3.1 | N38: 5.9 | O38: 3.9 | P38: 5.6 | Q38: 6.3 | R38: 2.9 | V38: =G38*'IAA digestibility'!G38 -> 1.32 | W38: =H38*'IAA digestibility'!H38 -> 3.154 | X38: =I38*'IAA digestibility'!I38 -> 4.005 | Y38: =J38*'IAA digestibility'!J38 -> 7.65 | Z38: =K38*'IAA digestibility'!K38 -> 2.916 | AA38: =L38*'IAA digestibility'!L38 -> 1.78 | AB38: =M38*'IAA digestibility'!M38 -> 2.821 | AC38: =N38*'IAA digestibility'!N38 -> 5.369 | ... AE38: =P38*'IAA digestibility'!P38 -> 4.816 | AF38: =R38*'IAA digestibility'!R38 -> 2.61 | AH38: =(V38/$F38)*1000 -> 10.47619 | AI38: =(W38/$F38)*1000 -> 25.031746 | AJ38: =(X38/$F38)*1000 -> 31.785714 | AK38: =(Y38/$F38)*1000 -> 60.714286 | AL38: =(Z38/$F38)*1000 -> 23.142857 | AM38: =((AA38+AB38)/$F38)*1000 -> 36.515873 | AN38: =((AC38+AD38)/$F38)*1000 -> 70.468254 | AO38: =(AE38/$F38)*1000 -> 38.222222 | AP38: =(AF38/$F38)*1000 -> 20.714286
A39: Wheat flour (fibre < 3,5%) | B39: Cereal & cereal products | C39: 1,19 | E39: Standardized Ileal | F39: 154 | G39: 2.2 | H39: 5.1 | I39: 4.9 | J39: 9.5 | K39: 6.1 | L39: 2.5 | M39: 3.2 | N39: 6.1 | O39: 4.5 | P39: 7.2 | Q39: 10.3 | R39: 4.2 | V39: =G39*'IAA digestibility'!G39 -> 1.958 | W39: =H39*'IAA digestibility'!H39 -> 4.386 | X39: =I39*'IAA digestibility'!I39 -> 4.41 | Y39: =J39*'IAA digestibility'!J39 -> 8.645 | Z39: =K39*'IAA digestibility'!K39 -> 5.307 | AA39: =L39*'IAA digestibility'!L39 -> 2.25 | AB39: =M39*'IAA digestibility'!M39 -> 2.752 | AC39: =N39*'IAA digestibility'!N39 -> 5.429 | ... AE39: =P39*'IAA digestibility'!P39 -> 6.48 | AF39: =R39*'IAA digestibility'!R39 -> 3.822 | AH39: =(V39/$F39)*1000 -> 12.714286 | AI39: =(W39/$F39)*1000 -> 28.480519 | AJ39: =(X39/$F39)*1000 -> 28.636364 | AK39: =(Y39/$F39)*1000 -> 56.136364 | AL39: =(Z39/$F39)*1000 -> 34.461039 | AM39: =((AA39+AB39)/$F39)*1000 -> 32.480519 | AN39: =((AC39+AD39)/$F39)*1000 -> 62.136364 | AO39: =(AE39/$F39)*1000 -> 42.077922 | AP39: =(AF39/$F39)*1000 -> 24.818182
A40: Wheat (11,9% protein) | B40: Cereal & cereal products | C40: 7 | E40: Standardized Ileal | F40: 119 | G40: 1.3 | H40: 3.2 | I40: 3.9 | J40: 7.3 | K40: 3.4 | L40: 1.9 | M40: 2.5 | N40: 4.9 | O40: 2.7 | P40: 4.9 | Q40: 5.4 | R40: 2.5 | S40: Pocured from Siemer Enterprises Inc | V40: =G40*'IAA digestibility'!G40 -> 1.092 | W40: =H40*'IAA digestibility'!H40 -> 2.08 | X40: =I40*'IAA digestibility'!I40 -> 3.081 | Y40: =J40*'IAA digestibility'!J40 -> 5.913 | Z40: =K40*'IAA digestibility'!K40 -> 2.482 | AA40: =L40*'IAA digestibility'!L40 -> 1.615 | AB40: =M40*'IAA digestibility'!M40 -> 2.075 | AC40: =N40*'IAA digestibility'!N40 -> 4.116 | ... AE40: =P40*'IAA digestibility'!P40 -> 3.675 | AF40: =R40*'IAA digestibility'!R40 -> 2.1 | AH40: =(V40/$F40)*1000 -> 9.1764706 | AI40: =(W40/$F40)*1000 -> 17.478992 | AJ40: =(X40/$F40)*1000 -> 25.890756 | AK40: =(Y40/$F40)*1000 -> 49.689076 | AL40: =(Z40/$F40)*1000 -> 20.857143 | AM40: =((AA40+AB40)/$F40)*1000 -> 31.008403 | AN40: =((AC40+AD40)/$F40)*1000 -> 51.378151 | AO40: =(AE40/$F40)*1000 -> 30.882353 | AP40: =(AF40/$F40)*1000 -> 17.647059
...

Sheet DIAAS (birth to 6 months)
A1: Food item name | B1: Food group | C1: TRP | D1: THR | E1: ILE | F1: LEU | G1: LYS | H1: SAA | I1: AAA | J1: VAL | K1: HIS | L1: Final DIAAS Score | M1: 1st Limiting AA | N1: Additional information
B2: (Reference pattern) | C2: 17 | D2: 44 | E2: 55 | F2: 96 | G2: 69 | H2: 33 | I2: 94 | J2: 55 | K2: 21
A3: Barley (not hulless varieties) | B3: Cereal & cereal products | C3: ='Total and digestible IAA'!AH3/$C$2 -> 0.5757418 | D3: ='Total and digestible IAA'!AI3/$D$2 -> 0.58829445 | E3: ='Total and digestible IAA'!AJ3/$E$2 -> 0.53435237 | F3: ='Total and digestible IAA'!AK3/$F$2 -> 0.58914086 | G3: ='Total and digestible IAA'!AL3/$G$2 -> 0.41362062 | H3: ='Total and digestible IAA'!AM3/$H$2 -> 1.0085814 | I3: ='Total and digestible IAA'!AN3/$I$2 -> 0.68499341 | J3: ='Total and digestible IAA'!AO3/$J$2 -> 0.73370877 | K3: ='Total and digestible IAA'!AP3/$K$2 -> 0.8874842 | L3: =MIN(C3:K3)*100 -> 41.362062 | M3: Lysine
A4: Barley, dehulled (11,8% protein) | B4: Cereal & cereal products | C4: ='Total and digestible IAA'!AH4/$C$2 -> 0.41874377 | D4: ='Total and digestible IAA'!AI4/$D$2 -> 0.47149461 | E4: ='Total and digestible IAA'!AJ4/$E$2 -> 0.45670262 | F4: ='Total and digestible IAA'!AK4/$F$2 -> 0.50909251 | G4: ='Total and digestible IAA'!AL4/$G$2 -> 0.35445836 | H4: ='Total and digestible IAA'!AM4/$H$2 -> 0.81304571 | I4: ='Total and digestible IAA'!AN4/$I$2 -> 0.59403173 | J4: ='Total and digestible IAA'!AO4/$J$2 -> 0.62881356 | K4: ='Total and digestible IAA'!AP4/$K$2 -> 0.81719128 | L4: =MIN(C4:K4)*100 -> 35.445836 | M4: Lysine
A5: Biscuits (CP>12%) | B5: Cereal & cereal products | C5: ='Total and digestible IAA'!AH5/$C$2 -> 0.49963689 | D5: ='Total and digestible IAA'!AI5/$D$2 -> 0.68939394 | E5: ='Total and digestible IAA'!AJ5/$E$2 -> 0.59887767 | F5: ='Total and digestible IAA'!AK5/$F$2 -> 0.63194444 | G5: ='Total and digestible IAA'!AL5/$G$2 -> 0.31848273 | H5: ='Total and digestible IAA'!AM5/$H$2 -> 0.95735129 | I5: ='Total and digestible IAA'!AN5/$I$2 -> 0.71158392 | J5: ='Total and digestible IAA'!AO5/$J$2 -> 0.74747475 | K5: ='Total and digestible IAA'!AP5/$K$2 -> 1.0388007 | L5: =MIN(C5:K5)*100 -> 31.848273 | M5: Lysine
A6: Bread | B6: Cereal & cereal products | C6: ='Total and digestible IAA'!AH6/$C$2 -> 0.52503646 | D6: ='Total and digestible IAA'!AI6/$D$2 -> 0.68369647 | E6: ='Total and digestible IAA'!AJ6/$E$2 -> 0.60826446 | F6: ='Total and digestible IAA'!AK6/$F$2 -> 0.64049587 | G6: ='Total and digestible IAA'!AL6/$G$2 -> 0.33057851 | H6: ='Total and digestible IAA'!AM6/$H$2 -> 0.98572502 | I6: ='Total and digestible IAA'!AN6/$I$2 -> 0.71127132 | J6: ='Total and digestible IAA'!AO6/$J$2 -> 0.75206612 | K6: ='Total and digestible IAA'!AP6/$K$2 -> 1.0499803 | L6: =MIN(C6:K6)*100 -> 33.057851 | M6: Lysine
A7: Maize flour/Corn flour | B7: Cereal & cereal products | C7: ='Total and digestible IAA'!AH7/$C$2 -> 0.30185759 | D7: ='Total and digestible IAA'!AI7/$D$2 -> 0.61363636 | E7: ='Total and digestible IAA'!AJ7/$E$2 -> 0.53492823 | F7: ='Total and digestible IAA'!AK7/$F$2 -> 1.1600877 | G7: ='Total and digestible IAA'!AL7/$G$2 -> 0.31884058 | H7: ='Total and digestible IAA'!AM7/$H$2 -> 1.1224083 | I7: ='Total and digestible IAA'!AN7/$I$2 -> 0.79171333 | J7: ='Total and digestible IAA'!AO7/$J$2 -> 0.75239234 | K7: ='Total and digestible IAA'!AP7/$K$2 -> 1.2105263 | L7: =MIN(C7:K7)*100 -> 30.185759 | M7: Lysine
A8: Maize/corn | B8: Cereal & cereal products | C8: ='Total and digestible IAA'!AH8/$C$2 -> 0.32085561 | D8: ='Total and digestible IAA'!AI8/$D$2 -> 0.70738636 | E8: ='Total and digestible IAA'!AJ8/$E$2 -> 0.6 | F8: ='Total and digestible IAA'!AK8/$F$2 -> 1.1889205 | G8: ='Total and digestible IAA'!AL8/$G$2 -> 0.35573123 | H8: ='Total and digestible IAA'!AM8/$H$2 -> 1.2696281 | I8: ='Total and digestible IAA'!AN8/$I$2 -> 0.87560445 | J8: ='Total and digestible IAA'!AO8/$J$2 -> 0.79090909 | K8: ='Total and digestible IAA'!AP8/$K$2 -> 1.2521645 | L8: =MIN(C8:K8)*100 -> 32.085561 | M8: Tryptophan
A9: Maize (extruded)/extruded corn | B9: Cereal & cereal products | C9: ='Total and digestible IAA'!AH9/$C$2 -> 0.3328877 | D9: ='Total and digestible IAA'!AI9/$D$2 -> 0.69034091 | E9: ='Total and digestible IAA'!AJ9/$E$2 -> 0.59318182 | F9: ='Total and digestible IAA'!AK9/$F$2 -> 1.1633523 | G9: ='Total and digestible IAA'!AL9/$G$2 -> 0.35128458 | H9: ='Total and digestible IAA'!AM9/$H$2 -> 1.2413912 | I9: ='Total and digestible IAA'!AN9/$I$2 -> 0.86593327 | J9: ='Total and digestible IAA'!AO9/$J$2 -> 0.78181818 | K9: ='Total and digestible IAA'!AP9/$K$2 -> 1.224026 | L9: =MIN(C9:K9)*100 -> 33.28877 | M9: Tryptophan
A10: Maize (flaked)/flaked corn/rolled corn | B10: Cereal & cereal products | C10: ='Total and digestible IAA'!AH10/$C$2 -> 0.3328877 | D10: ='Total and digestible IAA'!AI10/$D$2 -> 0.69034091 | E10: ='Total and digestible IAA'!AJ10/$E$2 -> 0.59318182 | F10: ='Total and digestible IAA'!AK10/$F$2 -> 1.1633523 | G10: ='Total and digestible IAA'!AL10/$G$2 -> 0.35128458 | H10: ='Total and digestible IAA'!AM10/$H$2 -> 1.2413912 | I10: ='Total and digestible IAA'!AN10/$I$2 -> 0.86593327 | J10: ='Total and digestible IAA'!AO10/$J$2 -> 0.78181818 | K10: ='Total and digestible IAA'!AP10/$K$2 -> 1.224026 | L10: =MIN(C10:K10)*100 -> 33.28877 | M10: Tryptophan
A11: Maize (high moisure)/humid corn - 60-70% dry matter, raw | B11: Cereal & cereal products | C11: ='Total and digestible IAA'!AH11/$C$2 -> 0.30690537 | D11: ='Total and digestible IAA'!AI11/$D$2 -> 0.69713439 | E11: ='Total and digestible IAA'!AJ11/$E$2 -> 0.59130435 | F11: ='Total and digestible IAA'!AK11/$F$2 -> 1.2004076 | G11: ='Total and digestible IAA'!AL11/$G$2 -> 0.35286704 | H11: ='Total and digestible IAA'!AM11/$H$2 -> 1.236166 | I11: ='Total and digestible IAA'!AN11/$I$2 -> 0.87939408 | J11: ='Total and digestible IAA'!AO11/$J$2 -> 0.79090909 | K11: ='Total and digestible IAA'!AP11/$K$2 -> 1.2437888 | L11: =MIN(C11:K11)*100 -> 30.690537 | M11: Tryptophan
A12: Maize bran | B12: Cereal & cereal products | C12: ='Total and digestible IAA'!AH12/$C$2 -> 0.30225282 | D12: ='Total and digestible IAA'!AI12/$D$2 -> 0.55851064 | E12: ='Total and digestible IAA'!AJ12/$E$2 -> 0.49148936 | F12: ='Total and digestible IAA'!AK12/$F$2 -> 0.9424867 | G12: ='Total and digestible IAA'!AL12/$G$2 -> 0.31452359 | H12: ='Total and digestible IAA'!AM12/$H$2 -> 1.0022566 | I12: ='Total and digestible IAA'!AN12/$I$2 -> 0.7062019 | J12: ='Total and digestible IAA'!AO12/$J$2 -> 0.71489362 | K12: ='Total and digestible IAA'!AP12/$K$2 -> 1.0942249 | L12: =MIN(C12:K12)*100 -> 30.225282 | M12: Tryptophan
A13: Maize, yellow dent (7,5% protein) | B13: Cereal & cereal products | C13: ='Total and digestible IAA'!AH13/$C$2 -> 0.2745098 | D13: ='Total and digestible IAA'!AI13/$D$2 -> 0.48787879 | E13: ='Total and digestible IAA'!AJ13/$E$2 -> 0.42375758 | F13: ='Total and digestible IAA'!AK13/$F$2 -> 0.82833333 | G13: ='Total and digestible IAA'!AL13/$G$2 -> 0.33333333 | H13: ='Total and digestible IAA'!AM13/$H$2 -> 0.94464646 | I13: ='Total and digestible IAA'!AN13/$I$2 -> 0.55702128 | J13: ='Total and digestible IAA'!AO13/$J$2 -> 0.58181818 | K13: ='Total and digestible IAA'!AP13/$K$2 -> 1.0012698 | L13: =MIN(C13:K13)*100 -> 27.45098 | M13: Tryptophan
A14: Maize, nutridense (8,8% protein) | B14: Cereal & cereal products | C14: ='Total and digestible IAA'!AH14/$C$2 -> 0.24398396 | D14: ='Total and digestible IAA'!AI14/$D$2 -> 0.52995868 | E14: ='Total and digestible IAA'!AJ14/$E$2 -> 0.50206612 | F14: ='Total and digestible IAA'!AK14/$F$2 -> 1.0227273 | G14: ='Total and digestible IAA'!AL14/$G$2 -> 0.37730567 | H14: ='Total and digestible IAA'!AM14/$H$2 -> 1.012741 | I14: ='Total and digestible IAA'!AN14/$I$2 -> 0.6615087 | J14: ='Total and digestible IAA'!AO14/$J$2 -> 0.67768595 | K14: ='Total and digestible IAA'!AP14/$K$2 -> 1.224026 | L14: =MIN(C14:K14)*100 -> 24.398396 | M14: Tryptophan
A15: Maize, high lysine | B15: Cereal & cereal products
A16: Millet, finger | B16: Cereal & cereal products
A17: Millet, pearl (Penisetum glaucum (l) R. Br)/candle millet/dark millet/bajra/Indian millet/horse millet/bulrush millet/cattail millet | B17: Cereal & cereal products | C17: ='Total and digestible IAA'!AH17/$C$2 -> 0.95247059 | D17: ='Total and digestible IAA'!AI17/$D$2 -> 0.77509091 | E17: ='Total and digestible IAA'!AJ17/$E$2 -> 0.728 | F17: ='Total and digestible IAA'!AK17/$F$2 -> 1.2436667 | G17: ='Total and digestible IAA'!AL17/$G$2 -> 0.30910145 | H17: ='Total and digestible IAA'!AM17/$H$2 -> 1.5301818 | I17: ='Total and digestible IAA'!AN17/$I$2 -> 0.77157447 | J17: ='Total and digestible IAA'!AO17/$J$2 -> 0.89018182 | K17: ='Total and digestible IAA'!AP17/$K$2 -> 1.016381 | L17: =MIN(C17:K17)*100 -> 30.910145 | M17: Lysine
A18: Millet, proso (Panicum miliaceum L.)/common millet/broomtail millet/hog millet/white millet/broomcorn millet | B18: Cereal & cereal products | C18: ='Total and digestible IAA'!AH18/$C$2 -> 0.82932891 | D18: ='Total and digestible IAA'!AI18/$D$2 -> 0.65685019 | E18: ='Total and digestible IAA'!AJ18/$E$2 -> 0.6637644 | F18: ='Total and digestible IAA'!AK18/$F$2 -> 1.1568369 | G18: ='Total and digestible IAA'!AL18/$G$2 -> 0.25147989 | H18: ='Total and digestible IAA'!AM18/$H$2 -> 1.4244558 | I18: ='Total and digestible IAA'!AN18/$I$2 -> 0.7108181 | J18: ='Total and digestible IAA'!AO18/$J$2 -> 0.77887324 | K18: ='Total and digestible IAA'!AP18/$K$2 -> 0.85244802 | L18: =MIN(C18:K18)*100 -> 25.147989 | M18: Lysine
